<?xml version="1.0" encoding="utf-8"?>
<!-- =================================================================================== -->
<!-- |    This document was autogenerated by xacro from hrwros.xacro                   | -->
<!-- |    EDITING THIS FILE BY HAND IS NOT RECOMMENDED                                 | -->
<!-- =================================================================================== -->
<robot name="hrwros">
  <!-- world -->
  <link name="world"/>
  <!-- Links -->
  <link name="world_interface"/>
  <link name="workcell">
    <visual>
      <geometry>
        <mesh filename="package://hrwros_support/meshes/workcell/visual/workcell.dae"/>
      </geometry>
    </visual>
    <collision>
      <geometry>
        <mesh filename="package://hrwros_support/meshes/workcell/collision/workcell.dae"/>
      </geometry>
    </collision>
    <inertial>
      <inertia ixx="1.0" ixy="0" ixz="0" iyy="1.0" iyz="0" izz="1.0"/>
      <mass value="100"/>
    </inertial>
  </link>
  <joint name="workcell_to_world_interface" type="fixed">
    <parent link="world_interface"/>
    <child link="workcell"/>
    <origin rpy="0 0 1.57079632679" xyz="0 0 0"/>
  </joint>
  <joint name="robot1_pedestal_joint" type="fixed">
    <origin rpy="0 0 0" xyz="0.5 1.8 0.0"/>
    <parent link="world_interface"/>
    <child link="robot1_pedestal_link"/>
  </joint>
  <link name="robot1_pedestal_link">
    <visual>
      <origin xyz="0 0 0.475"/>
      <geometry>
        <box size="0.3 0.3 0.95"/>
      </geometry>
      <material name="pedestal_color">
        <color rgba="0 0.156862745098 0.525490196078 1"/>
      </material>
    </visual>
    <collision>
      <origin xyz="0 0 0.475"/>
      <geometry>
        <box size="0.3 0.3 0.95"/>
      </geometry>
    </collision>
    <inertial>
      <mass value="500"/>
      <origin rpy="0 0 0" xyz="0 0 0"/>
      <inertia ixx="0.001" ixy="0" ixz="0" iyy="0.001" iyz="0" izz="0.001"/>
    </inertial>
  </link>
  <gazebo reference="robot1_pedestal_link">
    <material>Gazebo/Blue</material>
  </gazebo>
  <!--
  Author: Kelsey Hawkins
  Contributers: Jimmy Da Silva, Ajit Krisshna N L, Muhammad Asif Rana
-->
  <!-- measured from model -->
  <link name="robot1_base_link">
    <visual>
      <geometry>
        <mesh filename="package://ur_description/meshes/ur10/visual/base.dae"/>
      </geometry>
      <material name="LightGrey">
        <color rgba="0.7 0.7 0.7 1.0"/>
      </material>
    </visual>
    <collision>
      <geometry>
        <mesh filename="package://ur_description/meshes/ur10/collision/base.stl"/>
      </geometry>
    </collision>
    <inertial>
      <mass value="4.0"/>
      <origin rpy="0 0 0" xyz="0.0 0.0 0.0"/>
      <inertia ixx="0.0061063308908" ixy="0.0" ixz="0.0" iyy="0.0061063308908" iyz="0.0" izz="0.01125"/>
    </inertial>
  </link>
  <joint name="robot1_shoulder_pan_joint" type="revolute">
    <parent link="robot1_base_link"/>
    <child link="robot1_shoulder_link"/>
    <origin rpy="0.0 0.0 0.0" xyz="0.0 0.0 0.1273"/>
    <axis xyz="0 0 1"/>
    <limit effort="330.0" lower="-3.14159265359" upper="3.14159265359" velocity="2.16"/>
    <dynamics damping="0.0" friction="0.0"/>
  </joint>
  <link name="robot1_shoulder_link">
    <visual>
      <geometry>
        <mesh filename="package://ur_description/meshes/ur10/visual/shoulder.dae"/>
      </geometry>
      <material name="LightGrey">
        <color rgba="0.7 0.7 0.7 1.0"/>
      </material>
    </visual>
    <collision>
      <geometry>
        <mesh filename="package://ur_description/meshes/ur10/collision/shoulder.stl"/>
      </geometry>
    </collision>
    <inertial>
      <mass value="7.778"/>
      <origin rpy="0 0 0" xyz="0.0 0.0 0.0"/>
      <inertia ixx="0.0314743125769" ixy="0.0" ixz="0.0" iyy="0.0314743125769" iyz="0.0" izz="0.021875625"/>
    </inertial>
  </link>
  <joint name="robot1_shoulder_lift_joint" type="revolute">
    <parent link="robot1_shoulder_link"/>
    <child link="robot1_upper_arm_link"/>
    <origin rpy="0.0 1.57079632679 0.0" xyz="0.0 0.220941 0.0"/>
    <axis xyz="0 1 0"/>
    <limit effort="330.0" lower="-3.14159265359" upper="3.14159265359" velocity="2.16"/>
    <dynamics damping="0.0" friction="0.0"/>
  </joint>
  <link name="robot1_upper_arm_link">
    <visual>
      <geometry>
        <mesh filename="package://ur_description/meshes/ur10/visual/upperarm.dae"/>
      </geometry>
      <material name="LightGrey">
        <color rgba="0.7 0.7 0.7 1.0"/>
      </material>
    </visual>
    <collision>
      <geometry>
        <mesh filename="package://ur_description/meshes/ur10/collision/upperarm.stl"/>
      </geometry>
    </collision>
    <inertial>
      <mass value="12.93"/>
      <origin rpy="0 0 0" xyz="0.0 -0.045 0.306"/>
      <inertia ixx="0.421753803798" ixy="0.0" ixz="0.0" iyy="0.421753803798" iyz="0.0" izz="0.036365625"/>
    </inertial>
  </link>
  <joint name="robot1_elbow_joint" type="revolute">
    <parent link="robot1_upper_arm_link"/>
    <child link="robot1_forearm_link"/>
    <origin rpy="0.0 0.0 0.0" xyz="0.0 -0.1719 0.612"/>
    <axis xyz="0 1 0"/>
    <limit effort="150.0" lower="-3.14159265359" upper="3.14159265359" velocity="3.15"/>
    <dynamics damping="0.0" friction="0.0"/>
  </joint>
  <link name="robot1_forearm_link">
    <visual>
      <geometry>
        <mesh filename="package://ur_description/meshes/ur10/visual/forearm.dae"/>
      </geometry>
      <material name="LightGrey">
        <color rgba="0.7 0.7 0.7 1.0"/>
      </material>
    </visual>
    <collision>
      <geometry>
        <mesh filename="package://ur_description/meshes/ur10/collision/forearm.stl"/>
      </geometry>
    </collision>
    <inertial>
      <mass value="3.87"/>
      <origin rpy="0 0 0" xyz="0.0 0.0 0.28615"/>
      <inertia ixx="0.111069694097" ixy="0.0" ixz="0.0" iyy="0.111069694097" iyz="0.0" izz="0.010884375"/>
    </inertial>
  </link>
  <joint name="robot1_wrist_1_joint" type="revolute">
    <parent link="robot1_forearm_link"/>
    <child link="robot1_wrist_1_link"/>
    <origin rpy="0.0 1.57079632679 0.0" xyz="0.0 0.0 0.5723"/>
    <axis xyz="0 1 0"/>
    <limit effort="54.0" lower="-3.14159265359" upper="3.14159265359" velocity="3.2"/>
    <dynamics damping="0.0" friction="0.0"/>
  </joint>
  <link name="robot1_wrist_1_link">
    <visual>
      <geometry>
        <mesh filename="package://ur_description/meshes/ur10/visual/wrist1.dae"/>
      </geometry>
      <material name="LightGrey">
        <color rgba="0.7 0.7 0.7 1.0"/>
      </material>
    </visual>
    <collision>
      <geometry>
        <mesh filename="package://ur_description/meshes/ur10/collision/wrist1.stl"/>
      </geometry>
    </collision>
    <inertial>
      <mass value="1.96"/>
      <origin rpy="0 0 0" xyz="0.0 0.1149 0.0"/>
      <inertia ixx="0.0051082479567" ixy="0.0" ixz="0.0" iyy="0.0051082479567" iyz="0.0" izz="0.0055125"/>
    </inertial>
  </link>
  <joint name="robot1_wrist_2_joint" type="revolute">
    <parent link="robot1_wrist_1_link"/>
    <child link="robot1_wrist_2_link"/>
    <origin rpy="0.0 0.0 0.0" xyz="0.0 0.1149 0.0"/>
    <axis xyz="0 0 1"/>
    <limit effort="54.0" lower="-3.14159265359" upper="3.14159265359" velocity="3.2"/>
    <dynamics damping="0.0" friction="0.0"/>
  </joint>
  <link name="robot1_wrist_2_link">
    <visual>
      <geometry>
        <mesh filename="package://ur_description/meshes/ur10/visual/wrist2.dae"/>
      </geometry>
      <material name="LightGrey">
        <color rgba="0.7 0.7 0.7 1.0"/>
      </material>
    </visual>
    <collision>
      <geometry>
        <mesh filename="package://ur_description/meshes/ur10/collision/wrist2.stl"/>
      </geometry>
    </collision>
    <inertial>
      <mass value="1.96"/>
      <origin rpy="0 0 0" xyz="0.0 0.0 0.1157"/>
      <inertia ixx="0.0051082479567" ixy="0.0" ixz="0.0" iyy="0.0051082479567" iyz="0.0" izz="0.0055125"/>
    </inertial>
  </link>
  <joint name="robot1_wrist_3_joint" type="revolute">
    <parent link="robot1_wrist_2_link"/>
    <child link="robot1_wrist_3_link"/>
    <origin rpy="0.0 0.0 0.0" xyz="0.0 0.0 0.1157"/>
    <axis xyz="0 1 0"/>
    <limit effort="54.0" lower="-3.14159265359" upper="3.14159265359" velocity="3.2"/>
    <dynamics damping="0.0" friction="0.0"/>
  </joint>
  <link name="robot1_wrist_3_link">
    <visual>
      <geometry>
        <mesh filename="package://ur_description/meshes/ur10/visual/wrist3.dae"/>
      </geometry>
      <material name="LightGrey">
        <color rgba="0.7 0.7 0.7 1.0"/>
      </material>
    </visual>
    <collision>
      <geometry>
        <mesh filename="package://ur_description/meshes/ur10/collision/wrist3.stl"/>
      </geometry>
    </collision>
    <inertial>
      <mass value="0.202"/>
      <origin rpy="1.57079632679 0 0" xyz="0.0 0.07695 0.0"/>
      <inertia ixx="0.000117921661165" ixy="0.0" ixz="0.0" iyy="0.000117921661165" iyz="0.0" izz="0.000204525"/>
    </inertial>
  </link>
  <joint name="robot1_ee_fixed_joint" type="fixed">
    <parent link="robot1_wrist_3_link"/>
    <child link="robot1_ee_link"/>
    <origin rpy="0.0 0.0 1.57079632679" xyz="0.0 0.0922 0.0"/>
  </joint>
  <link name="robot1_ee_link">
    <collision>
      <geometry>
        <box size="0.01 0.01 0.01"/>
      </geometry>
      <origin rpy="0 0 0" xyz="-0.01 0 0"/>
    </collision>
  </link>
  <transmission name="robot1_shoulder_pan_trans">
    <type>transmission_interface/SimpleTransmission</type>
    <joint name="robot1_shoulder_pan_joint">
      <hardwareInterface>hardware_interface/PositionJointInterface</hardwareInterface>
    </joint>
    <actuator name="robot1_shoulder_pan_motor">
      <mechanicalReduction>1</mechanicalReduction>
    </actuator>
  </transmission>
  <transmission name="robot1_shoulder_lift_trans">
    <type>transmission_interface/SimpleTransmission</type>
    <joint name="robot1_shoulder_lift_joint">
      <hardwareInterface>hardware_interface/PositionJointInterface</hardwareInterface>
    </joint>
    <actuator name="robot1_shoulder_lift_motor">
      <mechanicalReduction>1</mechanicalReduction>
    </actuator>
  </transmission>
  <transmission name="robot1_elbow_trans">
    <type>transmission_interface/SimpleTransmission</type>
    <joint name="robot1_elbow_joint">
      <hardwareInterface>hardware_interface/PositionJointInterface</hardwareInterface>
    </joint>
    <actuator name="robot1_elbow_motor">
      <mechanicalReduction>1</mechanicalReduction>
    </actuator>
  </transmission>
  <transmission name="robot1_wrist_1_trans">
    <type>transmission_interface/SimpleTransmission</type>
    <joint name="robot1_wrist_1_joint">
      <hardwareInterface>hardware_interface/PositionJointInterface</hardwareInterface>
    </joint>
    <actuator name="robot1_wrist_1_motor">
      <mechanicalReduction>1</mechanicalReduction>
    </actuator>
  </transmission>
  <transmission name="robot1_wrist_2_trans">
    <type>transmission_interface/SimpleTransmission</type>
    <joint name="robot1_wrist_2_joint">
      <hardwareInterface>hardware_interface/PositionJointInterface</hardwareInterface>
    </joint>
    <actuator name="robot1_wrist_2_motor">
      <mechanicalReduction>1</mechanicalReduction>
    </actuator>
  </transmission>
  <transmission name="robot1_wrist_3_trans">
    <type>transmission_interface/SimpleTransmission</type>
    <joint name="robot1_wrist_3_joint">
      <hardwareInterface>hardware_interface/PositionJointInterface</hardwareInterface>
    </joint>
    <actuator name="robot1_wrist_3_motor">
      <mechanicalReduction>1</mechanicalReduction>
    </actuator>
  </transmission>
  <gazebo reference="robot1_shoulder_link">
    <selfCollide>true</selfCollide>
  </gazebo>
  <gazebo reference="robot1_upper_arm_link">
    <selfCollide>true</selfCollide>
  </gazebo>
  <gazebo reference="robot1_forearm_link">
    <selfCollide>true</selfCollide>
  </gazebo>
  <gazebo reference="robot1_wrist_1_link">
    <selfCollide>true</selfCollide>
  </gazebo>
  <gazebo reference="robot1_wrist_3_link">
    <selfCollide>true</selfCollide>
  </gazebo>
  <gazebo reference="robot1_wrist_2_link">
    <selfCollide>true</selfCollide>
  </gazebo>
  <gazebo reference="robot1_ee_link">
    <selfCollide>true</selfCollide>
  </gazebo>
  <!-- ROS base_link to UR 'Base' Coordinates transform -->
  <link name="robot1_base"/>
  <joint name="robot1_base_link-base_fixed_joint" type="fixed">
    <!-- NOTE: this rotation is only needed as long as base_link itself is
                 not corrected wrt the real robot (ie: rotated over 180
                 degrees)
      -->
    <origin rpy="0 0 -3.14159265359" xyz="0 0 0"/>
    <parent link="robot1_base_link"/>
    <child link="robot1_base"/>
  </joint>
  <!-- Frame coincident with all-zeros TCP on UR controller -->
  <link name="robot1_tool0"/>
  <joint name="robot1_wrist_3_link-tool0_fixed_joint" type="fixed">
    <origin rpy="-1.57079632679 0 0" xyz="0 0.0922 0"/>
    <parent link="robot1_wrist_3_link"/>
    <child link="robot1_tool0"/>
  </joint>
  <!-- link list -->
  <link name="vacuum_gripper1_base_link">
    <visual>
      <origin rpy="0 0 0" xyz="0 0 0"/>
      <geometry>
        <mesh filename="package://hrwros_support/meshes/vacuum_gripper/visual/vacuum_gripper.dae"/>
      </geometry>
      <material name="red">
        <color rgba="1 0 0 1"/>
      </material>
    </visual>
    <collision>
      <origin rpy="0 0 0" xyz="0 0 0"/>
      <geometry>
        <mesh filename="package://hrwros_support/meshes/vacuum_gripper/collision/vacuum_gripper.dae"/>
      </geometry>
      <material name="red"/>
    </collision>
    <inertial>
      <origin rpy="0 0 0" xyz="0 0 0"/>
      <inertia ixx="1.0" ixy="0" ixz="0" iyy="1.0" iyz="0" izz="1.0"/>
      <mass value="1.0"/>
    </inertial>
  </link>
  <link name="vacuum_gripper1_suction_cup">
    <visual>
      <origin rpy="0 0 0" xyz="0 0 0"/>
      <geometry>
        <box size="0.001 0.001 0.001"/>
      </geometry>
      <material name="red">
        <color rgba="1 0 0 1"/>
      </material>
    </visual>
    <collision>
      <origin rpy="0 0 0" xyz="0 0 0"/>
      <geometry>
        <box size="0.001 0.001 0.001"/>
      </geometry>
      <material name="red"/>
    </collision>
    <inertial>
      <origin rpy="0 0 0" xyz="0 0 0"/>
      <inertia ixx="0.0001" ixy="0" ixz="0" iyy="0.0001" iyz="0" izz="0.0001"/>
      <mass value="0.00001"/>
    </inertial>
  </link>
  <!-- joint list -->
  <joint name="vacuum_gripper1_joint" type="fixed">
    <origin rpy="0 0 0" xyz="0 0 0.01"/>
    <parent link="vacuum_gripper1_base_link"/>
    <child link="vacuum_gripper1_suction_cup"/>
  </joint>
  <joint name="robot2_pedestal_joint" type="fixed">
    <origin rpy="0 0 0" xyz="-7.8 -1.5 0.0"/>
    <parent link="world_interface"/>
    <child link="robot2_pedestal_link"/>
  </joint>
  <link name="robot2_pedestal_link">
    <visual>
      <origin xyz="0 0 0.35"/>
      <geometry>
        <box size="0.3 0.3 0.7"/>
      </geometry>
      <material name="pedestal_color">
        <color rgba="0 0.156862745098 0.525490196078 1"/>
      </material>
    </visual>
    <collision>
      <origin xyz="0 0 0.35"/>
      <geometry>
        <box size="0.3 0.3 0.7"/>
      </geometry>
    </collision>
    <inertial>
      <mass value="500"/>
      <origin rpy="0 0 0" xyz="0 0 0"/>
      <inertia ixx="0.001" ixy="0" ixz="0" iyy="0.001" iyz="0" izz="0.001"/>
    </inertial>
  </link>
  <gazebo reference="robot2_pedestal_link">
    <material>Gazebo/Blue</material>
  </gazebo>
  <!-- measured from model -->
  <!--property name="shoulder_height" value="0.089159" /-->
  <!--property name="shoulder_offset" value="0.13585" /-->
  <!-- shoulder_offset - elbow_offset + wrist_1_length = 0.10915 -->
  <!--property name="upper_arm_length" value="0.42500" /-->
  <!--property name="elbow_offset" value="0.1197" /-->
  <!-- CAD measured -->
  <!--property name="forearm_length" value="0.39225" /-->
  <!--property name="wrist_1_length" value="0.093" /-->
  <!-- CAD measured -->
  <!--property name="wrist_2_length" value="0.09465" /-->
  <!-- In CAD this distance is 0.930, but in the spec it is 0.09465 -->
  <!--property name="wrist_3_length" value="0.0823" /-->
  <!-- manually measured -->
  <link name="robot2_base_link">
    <visual>
      <geometry>
        <mesh filename="package://ur_description/meshes/ur5/visual/base.dae"/>
      </geometry>
      <material name="LightGrey">
        <color rgba="0.7 0.7 0.7 1.0"/>
      </material>
    </visual>
    <collision>
      <geometry>
        <mesh filename="package://ur_description/meshes/ur5/collision/base.stl"/>
      </geometry>
    </collision>
    <inertial>
      <mass value="4.0"/>
      <origin rpy="0 0 0" xyz="0.0 0.0 0.0"/>
      <inertia ixx="0.00443333156" ixy="0.0" ixz="0.0" iyy="0.00443333156" iyz="0.0" izz="0.0072"/>
    </inertial>
  </link>
  <joint name="robot2_shoulder_pan_joint" type="revolute">
    <parent link="robot2_base_link"/>
    <child link="robot2_shoulder_link"/>
    <origin rpy="0.0 0.0 0.0" xyz="0.0 0.0 0.089159"/>
    <axis xyz="0 0 1"/>
    <limit effort="150.0" lower="-3.14159265359" upper="3.14159265359" velocity="3.15"/>
    <dynamics damping="0.0" friction="0.0"/>
  </joint>
  <link name="robot2_shoulder_link">
    <visual>
      <geometry>
        <mesh filename="package://ur_description/meshes/ur5/visual/shoulder.dae"/>
      </geometry>
      <material name="LightGrey">
        <color rgba="0.7 0.7 0.7 1.0"/>
      </material>
    </visual>
    <collision>
      <geometry>
        <mesh filename="package://ur_description/meshes/ur5/collision/shoulder.stl"/>
      </geometry>
    </collision>
    <inertial>
      <mass value="3.7"/>
      <origin rpy="0 0 0" xyz="0.0 0.0 0.0"/>
      <inertia ixx="0.010267495893" ixy="0.0" ixz="0.0" iyy="0.010267495893" iyz="0.0" izz="0.00666"/>
    </inertial>
  </link>
  <joint name="robot2_shoulder_lift_joint" type="revolute">
    <parent link="robot2_shoulder_link"/>
    <child link="robot2_upper_arm_link"/>
    <origin rpy="0.0 1.57079632679 0.0" xyz="0.0 0.13585 0.0"/>
    <axis xyz="0 1 0"/>
    <limit effort="150.0" lower="-3.14159265359" upper="3.14159265359" velocity="3.15"/>
    <dynamics damping="0.0" friction="0.0"/>
  </joint>
  <link name="robot2_upper_arm_link">
    <visual>
      <geometry>
        <mesh filename="package://ur_description/meshes/ur5/visual/upperarm.dae"/>
      </geometry>
      <material name="LightGrey">
        <color rgba="0.7 0.7 0.7 1.0"/>
      </material>
    </visual>
    <collision>
      <geometry>
        <mesh filename="package://ur_description/meshes/ur5/collision/upperarm.stl"/>
      </geometry>
    </collision>
    <inertial>
      <mass value="8.393"/>
      <origin rpy="0 0 0" xyz="0.0 0.0 0.28"/>
      <inertia ixx="0.22689067591" ixy="0.0" ixz="0.0" iyy="0.22689067591" iyz="0.0" izz="0.0151074"/>
    </inertial>
  </link>
  <joint name="robot2_elbow_joint" type="revolute">
    <parent link="robot2_upper_arm_link"/>
    <child link="robot2_forearm_link"/>
    <origin rpy="0.0 0.0 0.0" xyz="0.0 -0.1197 0.425"/>
    <axis xyz="0 1 0"/>
    <limit effort="150.0" lower="-3.14159265359" upper="3.14159265359" velocity="3.15"/>
    <dynamics damping="0.0" friction="0.0"/>
  </joint>
  <link name="robot2_forearm_link">
    <visual>
      <geometry>
        <mesh filename="package://ur_description/meshes/ur5/visual/forearm.dae"/>
      </geometry>
      <material name="LightGrey">
        <color rgba="0.7 0.7 0.7 1.0"/>
      </material>
    </visual>
    <collision>
      <geometry>
        <mesh filename="package://ur_description/meshes/ur5/collision/forearm.stl"/>
      </geometry>
    </collision>
    <inertial>
      <mass value="2.275"/>
      <origin rpy="0 0 0" xyz="0.0 0.0 0.196125"/>
      <inertia ixx="0.0312167910289" ixy="0.0" ixz="0.0" iyy="0.0312167910289" iyz="0.0" izz="0.004095"/>
    </inertial>
  </link>
  <joint name="robot2_wrist_1_joint" type="revolute">
    <parent link="robot2_forearm_link"/>
    <child link="robot2_wrist_1_link"/>
    <origin rpy="0.0 1.57079632679 0.0" xyz="0.0 0.0 0.39225"/>
    <axis xyz="0 1 0"/>
    <limit effort="28.0" lower="-3.14159265359" upper="3.14159265359" velocity="3.2"/>
    <dynamics damping="0.0" friction="0.0"/>
  </joint>
  <link name="robot2_wrist_1_link">
    <visual>
      <geometry>
        <mesh filename="package://ur_description/meshes/ur5/visual/wrist1.dae"/>
      </geometry>
      <material name="LightGrey">
        <color rgba="0.7 0.7 0.7 1.0"/>
      </material>
    </visual>
    <collision>
      <geometry>
        <mesh filename="package://ur_description/meshes/ur5/collision/wrist1.stl"/>
      </geometry>
    </collision>
    <inertial>
      <mass value="1.219"/>
      <origin rpy="0 0 0" xyz="0.0 0.093 0.0"/>
      <inertia ixx="0.00255989897604" ixy="0.0" ixz="0.0" iyy="0.00255989897604" iyz="0.0" izz="0.0021942"/>
    </inertial>
  </link>
  <joint name="robot2_wrist_2_joint" type="revolute">
    <parent link="robot2_wrist_1_link"/>
    <child link="robot2_wrist_2_link"/>
    <origin rpy="0.0 0.0 0.0" xyz="0.0 0.093 0.0"/>
    <axis xyz="0 0 1"/>
    <limit effort="28.0" lower="-3.14159265359" upper="3.14159265359" velocity="3.2"/>
    <dynamics damping="0.0" friction="0.0"/>
  </joint>
  <link name="robot2_wrist_2_link">
    <visual>
      <geometry>
        <mesh filename="package://ur_description/meshes/ur5/visual/wrist2.dae"/>
      </geometry>
      <material name="LightGrey">
        <color rgba="0.7 0.7 0.7 1.0"/>
      </material>
    </visual>
    <collision>
      <geometry>
        <mesh filename="package://ur_description/meshes/ur5/collision/wrist2.stl"/>
      </geometry>
    </collision>
    <inertial>
      <mass value="1.219"/>
      <origin rpy="0 0 0" xyz="0.0 0.0 0.09465"/>
      <inertia ixx="0.00255989897604" ixy="0.0" ixz="0.0" iyy="0.00255989897604" iyz="0.0" izz="0.0021942"/>
    </inertial>
  </link>
  <joint name="robot2_wrist_3_joint" type="revolute">
    <parent link="robot2_wrist_2_link"/>
    <child link="robot2_wrist_3_link"/>
    <origin rpy="0.0 0.0 0.0" xyz="0.0 0.0 0.09465"/>
    <axis xyz="0 1 0"/>
    <limit effort="28.0" lower="-3.14159265359" upper="3.14159265359" velocity="3.2"/>
    <dynamics damping="0.0" friction="0.0"/>
  </joint>
  <link name="robot2_wrist_3_link">
    <visual>
      <geometry>
        <mesh filename="package://ur_description/meshes/ur5/visual/wrist3.dae"/>
      </geometry>
      <material name="LightGrey">
        <color rgba="0.7 0.7 0.7 1.0"/>
      </material>
    </visual>
    <collision>
      <geometry>
        <mesh filename="package://ur_description/meshes/ur5/collision/wrist3.stl"/>
      </geometry>
    </collision>
    <inertial>
      <mass value="0.1879"/>
      <origin rpy="1.57079632679 0 0" xyz="0.0 0.06505 0.0"/>
      <inertia ixx="8.46958911216e-05" ixy="0.0" ixz="0.0" iyy="8.46958911216e-05" iyz="0.0" izz="0.0001321171875"/>
    </inertial>
  </link>
  <joint name="robot2_ee_fixed_joint" type="fixed">
    <parent link="robot2_wrist_3_link"/>
    <child link="robot2_ee_link"/>
    <origin rpy="0.0 0.0 1.57079632679" xyz="0.0 0.0823 0.0"/>
  </joint>
  <link name="robot2_ee_link">
    <collision>
      <geometry>
        <box size="0.01 0.01 0.01"/>
      </geometry>
      <origin rpy="0 0 0" xyz="-0.01 0 0"/>
    </collision>
  </link>
  <transmission name="robot2_shoulder_pan_trans">
    <type>transmission_interface/SimpleTransmission</type>
    <joint name="robot2_shoulder_pan_joint">
      <hardwareInterface>hardware_interface/PositionJointInterface</hardwareInterface>
    </joint>
    <actuator name="robot2_shoulder_pan_motor">
      <mechanicalReduction>1</mechanicalReduction>
    </actuator>
  </transmission>
  <transmission name="robot2_shoulder_lift_trans">
    <type>transmission_interface/SimpleTransmission</type>
    <joint name="robot2_shoulder_lift_joint">
      <hardwareInterface>hardware_interface/PositionJointInterface</hardwareInterface>
    </joint>
    <actuator name="robot2_shoulder_lift_motor">
      <mechanicalReduction>1</mechanicalReduction>
    </actuator>
  </transmission>
  <transmission name="robot2_elbow_trans">
    <type>transmission_interface/SimpleTransmission</type>
    <joint name="robot2_elbow_joint">
      <hardwareInterface>hardware_interface/PositionJointInterface</hardwareInterface>
    </joint>
    <actuator name="robot2_elbow_motor">
      <mechanicalReduction>1</mechanicalReduction>
    </actuator>
  </transmission>
  <transmission name="robot2_wrist_1_trans">
    <type>transmission_interface/SimpleTransmission</type>
    <joint name="robot2_wrist_1_joint">
      <hardwareInterface>hardware_interface/PositionJointInterface</hardwareInterface>
    </joint>
    <actuator name="robot2_wrist_1_motor">
      <mechanicalReduction>1</mechanicalReduction>
    </actuator>
  </transmission>
  <transmission name="robot2_wrist_2_trans">
    <type>transmission_interface/SimpleTransmission</type>
    <joint name="robot2_wrist_2_joint">
      <hardwareInterface>hardware_interface/PositionJointInterface</hardwareInterface>
    </joint>
    <actuator name="robot2_wrist_2_motor">
      <mechanicalReduction>1</mechanicalReduction>
    </actuator>
  </transmission>
  <transmission name="robot2_wrist_3_trans">
    <type>transmission_interface/SimpleTransmission</type>
    <joint name="robot2_wrist_3_joint">
      <hardwareInterface>hardware_interface/PositionJointInterface</hardwareInterface>
    </joint>
    <actuator name="robot2_wrist_3_motor">
      <mechanicalReduction>1</mechanicalReduction>
    </actuator>
  </transmission>
  <gazebo reference="robot2_shoulder_link">
    <selfCollide>true</selfCollide>
  </gazebo>
  <gazebo reference="robot2_upper_arm_link">
    <selfCollide>true</selfCollide>
  </gazebo>
  <gazebo reference="robot2_forearm_link">
    <selfCollide>true</selfCollide>
  </gazebo>
  <gazebo reference="robot2_wrist_1_link">
    <selfCollide>true</selfCollide>
  </gazebo>
  <gazebo reference="robot2_wrist_3_link">
    <selfCollide>true</selfCollide>
  </gazebo>
  <gazebo reference="robot2_wrist_2_link">
    <selfCollide>true</selfCollide>
  </gazebo>
  <gazebo reference="robot2_ee_link">
    <selfCollide>true</selfCollide>
  </gazebo>
  <!-- ROS base_link to UR 'Base' Coordinates transform -->
  <link name="robot2_base"/>
  <joint name="robot2_base_link-base_fixed_joint" type="fixed">
    <!-- NOTE: this rotation is only needed as long as base_link itself is
                 not corrected wrt the real robot (ie: rotated over 180
                 degrees)
      -->
    <origin rpy="0 0 -3.14159265359" xyz="0 0 0"/>
    <parent link="robot2_base_link"/>
    <child link="robot2_base"/>
  </joint>
  <!-- Frame coincident with all-zeros TCP on UR controller -->
  <link name="robot2_tool0"/>
  <joint name="robot2_wrist_3_link-tool0_fixed_joint" type="fixed">
    <origin rpy="-1.57079632679 0 0" xyz="0 0.0823 0"/>
    <parent link="robot2_wrist_3_link"/>
    <child link="robot2_tool0"/>
  </joint>
  <!-- link list -->
  <link name="vacuum_gripper2_base_link">
    <visual>
      <origin rpy="0 0 0" xyz="0 0 0"/>
      <geometry>
        <mesh filename="package://hrwros_support/meshes/vacuum_gripper/visual/vacuum_gripper.dae"/>
      </geometry>
      <material name="red">
        <color rgba="1 0 0 1"/>
      </material>
    </visual>
    <collision>
      <origin rpy="0 0 0" xyz="0 0 0"/>
      <geometry>
        <mesh filename="package://hrwros_support/meshes/vacuum_gripper/collision/vacuum_gripper.dae"/>
      </geometry>
      <material name="red"/>
    </collision>
    <inertial>
      <origin rpy="0 0 0" xyz="0 0 0"/>
      <inertia ixx="1.0" ixy="0" ixz="0" iyy="1.0" iyz="0" izz="1.0"/>
      <mass value="1.0"/>
    </inertial>
  </link>
  <link name="vacuum_gripper2_suction_cup">
    <visual>
      <origin rpy="0 0 0" xyz="0 0 0"/>
      <geometry>
        <box size="0.001 0.001 0.001"/>
      </geometry>
      <material name="red">
        <color rgba="1 0 0 1"/>
      </material>
    </visual>
    <collision>
      <origin rpy="0 0 0" xyz="0 0 0"/>
      <geometry>
        <box size="0.001 0.001 0.001"/>
      </geometry>
      <material name="red"/>
    </collision>
    <inertial>
      <origin rpy="0 0 0" xyz="0 0 0"/>
      <inertia ixx="0.0001" ixy="0" ixz="0" iyy="0.0001" iyz="0" izz="0.0001"/>
      <mass value="0.00001"/>
    </inertial>
  </link>
  <!-- joint list -->
  <joint name="vacuum_gripper2_joint" type="fixed">
    <origin rpy="0 0 0" xyz="0 0 0.01"/>
    <parent link="vacuum_gripper2_base_link"/>
    <child link="vacuum_gripper2_suction_cup"/>
  </joint>
  <!-- link list -->
  <link name="bin_1_base_link">
    <visual>
      <origin rpy="0 0 0" xyz="0 0 0"/>
      <geometry>
        <mesh filename="package://hrwros_support/meshes/bin/visual/bin.dae"/>
        <scale>0.6 0.6 0.6</scale>
      </geometry>
    </visual>
    <collision>
      <origin rpy="0 0 0" xyz="0 0 0"/>
      <geometry>
        <mesh filename="package://hrwros_support/meshes/bin/collision/bin_bottom.dae"/>
        <scale>0.6 0.6 0.6</scale>
      </geometry>
    </collision>
    <collision>
      <origin rpy="0 0 0" xyz="0 0 0"/>
      <geometry>
        <mesh filename="package://hrwros_support/meshes/bin/collision/bin_sides.dae"/>
        <scale>0.6 0.6 0.6</scale>
      </geometry>
    </collision>
    <inertial>
      <origin rpy="0 0 0" xyz="0 0 0"/>
      <inertia ixx="1.0" ixy="0" ixz="0" iyy="1.0" iyz="0" izz="1.0"/>
      <mass value="100"/>
    </inertial>
  </link>
  <link name="bin_1_drop_point">
    <inertial>
      <origin rpy="0 0 0" xyz="0 0 0"/>
      <inertia ixx="1.0" ixy="0" ixz="0" iyy="1.0" iyz="0" izz="1.0"/>
      <mass value="1.0"/>
    </inertial>
  </link>
  <!-- joint list -->
  <joint name="bin_1_joint_1" type="fixed">
    <origin rpy="0 0 0" xyz="0 0 1.0"/>
    <parent link="bin_1_base_link"/>
    <child link="bin_1_drop_point"/>
  </joint>
  <joint name="logical_camera1_logical_camera_joint" type="fixed">
    <origin rpy="0 1.5708 0" xyz="1.2 1.8 2.0"/>
    <parent link="world_interface"/>
    <child link="logical_camera1_base_link"/>
  </joint>
  <!-- link list -->
  <link name="logical_camera1_base_link">
    <visual>
      <origin rpy="0 0 0" xyz="0 0 0.025"/>
      <geometry>
        <box size="0.05 0.2 0.05"/>
      </geometry>
      <material name="dark_grey">
        <color rgba="0.1 0.1 0.1 1.0"/>
      </material>
    </visual>
    <collision>
      <origin rpy="0 0 0" xyz="0 0 0.025"/>
      <geometry>
        <box size="0.05 0.2 0.05"/>
      </geometry>
      <material name="dark_grey"/>
    </collision>
    <inertial>
      <origin rpy="0 0 0" xyz="0 0 0"/>
      <inertia ixx="0.1" ixy="0" ixz="0" iyy="0.1" iyz="0" izz="0.1"/>
      <mass value="1"/>
    </inertial>
  </link>
  <joint name="logical_camera2_logical_camera_joint" type="fixed">
    <origin rpy="0 1.5708 0" xyz="-8.3 -1.23 1.8"/>
    <parent link="world_interface"/>
    <child link="logical_camera2_base_link"/>
  </joint>
  <!-- link list -->
  <link name="logical_camera2_base_link">
    <visual>
      <origin rpy="0 0 0" xyz="0 0 0.025"/>
      <geometry>
        <box size="0.05 0.2 0.05"/>
      </geometry>
      <material name="dark_grey">
        <color rgba="0.1 0.1 0.1 1.0"/>
      </material>
    </visual>
    <collision>
      <origin rpy="0 0 0" xyz="0 0 0.025"/>
      <geometry>
        <box size="0.05 0.2 0.05"/>
      </geometry>
      <material name="dark_grey"/>
    </collision>
    <inertial>
      <origin rpy="0 0 0" xyz="0 0 0"/>
      <inertia ixx="0.1" ixy="0" ixz="0" iyy="0.1" iyz="0" izz="0.1"/>
      <mass value="1"/>
    </inertial>
  </link>
  <!-- link list -->
  <link name="break_beam_world_interface"/>
  <link name="break_beam_base_link">
    <visual>
      <origin rpy="0 0 0" xyz="0 0 0"/>
      <geometry>
        <mesh filename="package://hrwros_support/meshes/break_beam/visual/hokuyo.dae"/>
      </geometry>
      <material name="dark_grey">
        <color rgba="0.1 0.1 0.1 1.0"/>
      </material>
    </visual>
    <collision>
      <origin rpy="0 0 0" xyz="0 0 0"/>
      <geometry>
        <mesh filename="package://hrwros_support/meshes/break_beam/collision/hokuyo.dae"/>
      </geometry>
      <material name="dark_grey"/>
    </collision>
    <inertial>
      <origin rpy="0 0 0" xyz="0 0 0"/>
      <inertia ixx="0.1" ixy="0" ixz="0" iyy="0.1" iyz="0" izz="0.1"/>
      <mass value="1"/>
    </inertial>
  </link>
  <link name="break_beam_optical_link"/>
  <!-- joint list -->
  <joint name="break_beam_world_joint" type="fixed">
    <parent link="break_beam_world_interface"/>
    <child link="break_beam_base_link"/>
    <origin rpy="0 0 3.14159265359" xyz="1.6 1.9 0.925"/>
  </joint>
  <joint name="break_beam_joint_1" type="fixed">
    <parent link="break_beam_base_link"/>
    <child link="break_beam_optical_link"/>
    <origin rpy="0 0 0" xyz="0.025 0 0"/>
  </joint>
  <!-- Joints -->
  <joint name="world_interface_to_world" type="fixed">
    <parent link="world"/>
    <child link="world_interface"/>
  </joint>
  <!-- robot1-pedestal to world. -->
  <joint name="robot1_pedestal_to_world_interface" type="fixed">
    <parent link="world_interface"/>
    <child link="robot1_pedestal_link"/>
    <origin rpy="0.0 0.0 0.0" xyz="0.5 1.8 0.0"/>
  </joint>
  <!-- robot1 to pedestal. -->
  <joint name="robot1_to_pedestal" type="fixed">
    <origin rpy="0 0 0" xyz="0.5 1.8 0.95"/>
    <parent link="world_interface"/>
    <child link="robot1_base_link"/>
  </joint>
  <!-- gripper1 to robot1. -->
  <joint name="gripper1_to_robot1" type="fixed">
    <parent link="robot1_tool0"/>
    <child link="vacuum_gripper1_base_link"/>
  </joint>
  <!-- robot2-pedestal to world. -->
  <joint name="robot2_pedestal_to_world_interface" type="fixed">
    <parent link="world_interface"/>
    <child link="robot2_pedestal_link"/>
    <origin rpy="0.0 0.0 0.0" xyz="-7.8 -1.5 0.0"/>
  </joint>
  <!-- robot2 to pedestal. -->
  <joint name="robot2_to_pedestal" type="fixed">
    <parent link="world_interface"/>
    <child link="robot2_base_link"/>
    <origin rpy="0 0 1.57" xyz="-7.8 -1.5 0.7"/>
  </joint>
  <!-- gripper2 to robot2. -->
  <joint name="gripper2_to_robot2" type="fixed">
    <parent link="robot2_tool0"/>
    <child link="vacuum_gripper2_base_link"/>
  </joint>
  <!-- break beam to world. -->
  <joint name="break_beam_joint" type="fixed">
    <parent link="world_interface"/>
    <child link="break_beam_world_interface"/>
  </joint>
  <!-- bin to world. -->
  <joint name="bin_1_joint" type="fixed">
    <parent link="world_interface"/>
    <child link="bin_1_base_link"/>
    <origin rpy="0 0 0" xyz="-8.0 -2.2 0.0"/>
  </joint>
</robot>

